Workbook
Name StartingBalance: Agustus!$L$8
Name StartingBalance: April!$L$8
Name StartingBalance: February!$L$8
Name StartingBalance: Juli!$L$8
Name StartingBalance: Juni!$L$8
Name StartingBalance: March!$L$8
Name StartingBalance: Mei!$L$8
Name StartingBalance: Oktober!$L$8
Name StartingBalance: September!$L$8
Name StartingBalance: January!$L$8

Sheet Annual Graphic
C3: ABOUT THIS SHEET | K3: NOTE
C4: This sheet generates a summary of your spending based on data in the 'Expenses' and 'Income' tabs. | K4: Please don't edit this sheet.
C5: Make sure you've set a starting balance in the 'Setup' tab before beginning. | K5: It contains formulas and will update automatically.
C21: Summary
D22: ='Annual Expenses'!D2 -> 42370 | E22: ='Annual Expenses'!E2 -> 42401 | F22: ='Annual Expenses'!F2 -> 42430 | G22: ='Annual Expenses'!G2 -> 42461 | H22: ='Annual Expenses'!H2 -> 42491 | I22: ='Annual Expenses'!I2 -> 42522 | J22: ='Annual Expenses'!J2 -> 42552 | K22: ='Annual Expenses'!K2 -> 42583 | ... O22: ='Annual Expenses'!O2 -> 42705 | P22: Total | Q22: Average
C23: Income | D23: =SUM(D31:D36) -> 0 | E23: =SUM(E31:E36) -> 0 | F23: =SUM(F31:F36) -> 0 | G23: =SUM(G31:G36) -> 0 | H23: =SUM(H31:H36) -> 0 | I23: =SUM(I31:I36) -> 0 | J23: =SUM(J31:J36) -> 0 | K23: =SUM(K31:K36) -> 0 | L23: =SUM(L31:L41) -> 0 | M23: =SUM(M31:M41) -> 0 | N23: =SUM(N31:N41) -> #REF! | O23: =SUM(O31:O41) -> #REF! | P23: =SUM(D23:O23) -> #REF! | Q23: =AVERAGE(D23:O23) -> #REF!
C24: Expenses | D24: =SUM(D44:D58) -> 0 | E24: =SUM(E44:E58) -> 0 | F24: =SUM(F44:F58) -> 0 | G24: =SUM(G44:G58) -> 0 | H24: =SUM(H44:H58) -> 0 | I24: =SUM(I44:I58) -> 0 | J24: =SUM(J44:J58) -> 0 | K24: =SUM(K44:K58) -> 0 | ... O24: =SUM(O44:O58) -> #REF! | P24: =SUM(D24:O24) -> #REF! | Q24: =AVERAGE(D24:O24) -> #REF!
C25: Net savings | D25: =D23-D24 -> 0 | E25: =E23-E24 -> 0 | F25: =F23-F24 -> 0 | G25: =G23-G24 -> 0 | H25: =H23-H24 -> 0 | I25: =I23-I24 -> 0 | J25: =J23-J24 -> 0 | K25: =K23-K24 -> 0 | ... O25: =O23-O24 -> #REF! | P25: =SUM(D25:O25) -> #REF! | Q25: =AVERAGE(D25:O25) -> #REF!
C26: Ending balance | D26: =(January!L8+D23)-D24 -> 3000000 | E26: =(D26+E23)-E24 -> 3000000 | F26: =(E26+F23)-F24 -> 3000000 | G26: =(F26+G23)-G24 -> 3000000 | H26: =(G26+H23)-H24 -> 3000000 | I26: =(H26+I23)-I24 -> 3000000 | J26: =(I26+J23)-J24 -> 3000000 | K26: =(J26+K23)-K24 -> 3000000 | L26: =(K26+L23)-L24 -> 3000000 | ... O26: =(N26+O23)-O24 -> #REF! | P26: =SUM(D26:O26) -> #REF! | Q26: =AVERAGE(D26:O26) -> #REF!
C29: Income
B30: Row # | C30: =IFERROR(__xludf.DUMMYFUNCTION("unique('Annual Income'!A:A)"),"") | D30: =D22 -> 42370 | E30: =E22 -> 42401 | F30: =F22 -> 42430 | G30: =G22 -> 42461 | H30: =H22 -> 42491 | I30: =I22 -> 42522 | J30: =J22 -> 42552 | K30: =K22 -> 42583 | ... O30: =O22 -> 42705 | P30: Total | Q30: Average
B31: 4 | C31: =IFERROR(__xludf.DUMMYFUNCTION("""COMPUTED_VALUE"""),"Savings") -> Savings | D31: =IF(NOT(ISBLANK(B31)), INDIRECT("'Annual Income'!D"&B31&":Q"&B31),"") -> 0 | E31: 0 | F31: 0 | G31: 0 | H31: 0 | I31: 0 | J31: 0 | K31: 0 | L31: 0 | M31: 0 | N31: #REF! | O31: #REF! | P31: #REF! | Q31: 0
B32: 5 | C32: =IFERROR(__xludf.DUMMYFUNCTION("""COMPUTED_VALUE"""),"Paycheck") -> Paycheck | D32: =IF(NOT(ISBLANK(B32)), INDIRECT("'Annual Income'!D"&B32&":Q"&B32),"") -> 0 | E32: 0 | F32: 0 | G32: 0 | H32: 0 | I32: 0 | J32: 0 | K32: 0 | L32: 0 | M32: 0 | N32: #REF! | O32: #REF! | P32: #REF! | Q32: 0
B33: 6 | C33: =IFERROR(__xludf.DUMMYFUNCTION("""COMPUTED_VALUE"""),"Bonus") -> Bonus | D33: =IF(NOT(ISBLANK(B33)), INDIRECT("'Annual Income'!D"&B33&":Q"&B33),"") -> 0 | E33: 0 | F33: 0 | G33: 0 | H33: 0 | I33: 0 | J33: 0 | K33: 0 | L33: 0 | M33: 0 | N33: #REF! | O33: #REF! | P33: #REF! | Q33: 0
B34: 7 | C34: =IFERROR(__xludf.DUMMYFUNCTION("""COMPUTED_VALUE"""),"Interest") -> Interest | D34: =IF(NOT(ISBLANK(B34)), INDIRECT("'Annual Income'!D"&B34&":Q"&B34),"") -> 0 | E34: 0 | F34: 0 | G34: 0 | H34: 0 | I34: 0 | J34: 0 | K34: 0 | L34: 0 | M34: 0 | N34: #REF! | O34: #REF! | P34: #REF! | Q34: 0
B35: 8 | C35: =IFERROR(__xludf.DUMMYFUNCTION("""COMPUTED_VALUE"""),"Affiliate") -> Affiliate | D35: =IF(NOT(ISBLANK(B35)), INDIRECT("'Annual Income'!D"&B35&":Q"&B35),"") -> 0 | E35: 0 | F35: 0 | G35: 0 | H35: 0 | I35: 0 | J35: 0 | K35: 0 | L35: 0 | M35: 0 | N35: #REF! | O35: #REF! | P35: #REF! | Q35: 0
B36: 9 | C36: =IFERROR(__xludf.DUMMYFUNCTION("""COMPUTED_VALUE"""),"IKS") -> IKS | D36: =IF(NOT(ISBLANK(B36)), INDIRECT("'Annual Income'!D"&B36&":Q"&B36),"") -> 0 | E36: 0 | F36: 0 | G36: 0 | H36: 0 | I36: 0 | J36: 0 | K36: 0 | L36: 0 | M36: 0 | N36: #REF! | O36: #REF! | P36: #REF! | Q36: 0
B37: 10 | C37: =IFERROR(__xludf.DUMMYFUNCTION("""COMPUTED_VALUE"""),"Endorsement") -> Endorsement | D37: =IF(NOT(ISBLANK(B37)), INDIRECT("'Annual Income'!D"&B37&":Q"&B37),"") -> 0 | E37: 0 | F37: 0 | G37: 0 | H37: 0 | I37: 0 | J37: 0 | K37: 0 | L37: 0 | M37: 0 | N37: #REF! | O37: #REF! | P37: #REF! | Q37: 0
D38: =IF(NOT(ISBLANK(B38)), INDIRECT("'Annual Income'!D"&B38&":Q"&B38),"")
D39: =IF(NOT(ISBLANK(B39)), INDIRECT("Income!D"&B39&":Q"&B39),"")
D40: =IF(NOT(ISBLANK(B40)), INDIRECT("Income!D"&B40&":Q"&B40),"")
C42: Expenses
B43: Row # | C43: =IFERROR(__xludf.DUMMYFUNCTION("unique('Annual Expenses'!A:A)"),"") | D43: ='Annual Expenses'!D2 -> 42370 | E43: ='Annual Expenses'!E2 -> 42401 | F43: ='Annual Expenses'!F2 -> 42430 | G43: ='Annual Expenses'!G2 -> 42461 | H43: ='Annual Expenses'!H2 -> 42491 | I43: ='Annual Expenses'!I2 -> 42522 | J43: ='Annual Expenses'!J2 -> 42552 | K43: ='Annual Expenses'!K2 -> 42583 | ... O43: ='Annual Expenses'!O2 -> 42705 | P43: Total | Q43: Average
B44: 4 | C44: =IFERROR(__xludf.DUMMYFUNCTION("""COMPUTED_VALUE"""),"Food") -> Food | D44: =IF(NOT(ISBLANK(B44)), INDIRECT("'Annual Expenses'!D"&B44&":Q"&B44),"") -> 0 | E44: 0 | F44: 0 | G44: 0 | H44: 0 | I44: 0 | J44: 0 | K44: 0 | L44: 0 | M44: 0 | N44: #REF! | O44: #REF! | P44: #REF! | Q44: 0
B45: 5 | C45: =IFERROR(__xludf.DUMMYFUNCTION("""COMPUTED_VALUE"""),"Groceries") -> Groceries | D45: =IF(NOT(ISBLANK(B45)), INDIRECT("'Annual Expenses'!D"&B45&":Q"&B45),"") -> 0 | E45: 0 | F45: 0 | G45: 0 | H45: 0 | I45: 0 | J45: 0 | K45: 0 | L45: 0 | M45: 0 | N45: #REF! | O45: #REF! | P45: #REF! | Q45: 0
B46: 6 | C46: =IFERROR(__xludf.DUMMYFUNCTION("""COMPUTED_VALUE"""),"Internet") -> Internet | D46: =IF(NOT(ISBLANK(B46)), INDIRECT("'Annual Expenses'!D"&B46&":Q"&B46),"") -> 0 | E46: 0 | F46: 0 | G46: 0 | H46: 0 | I46: 0 | J46: 0 | K46: 0 | L46: 0 | M46: 0 | N46: #REF! | O46: #REF! | P46: #REF! | Q46: 0
B47: 7 | C47: =IFERROR(__xludf.DUMMYFUNCTION("""COMPUTED_VALUE"""),"Kids") -> Kids | D47: =IF(NOT(ISBLANK(B47)), INDIRECT("'Annual Expenses'!D"&B47&":Q"&B47),"") -> 0 | E47: 0 | F47: 0 | G47: 0 | H47: 0 | I47: 0 | J47: 0 | K47: 0 | L47: 0 | M47: 0 | N47: #REF! | O47: #REF! | P47: #REF! | Q47: 0
B48: 8 | C48: =IFERROR(__xludf.DUMMYFUNCTION("""COMPUTED_VALUE"""),"Transportation") -> Transportation | D48: =IF(NOT(ISBLANK(B48)), INDIRECT("'Annual Expenses'!D"&B48&":Q"&B48),"") -> 0 | E48: 0 | F48: 0 | G48: 0 | H48: 0 | I48: 0 | J48: 0 | K48: 0 | L48: 0 | M48: 0 | N48: #REF! | O48: #REF! | P48: #REF! | Q48: 0
B49: 9 | C49: =IFERROR(__xludf.DUMMYFUNCTION("""COMPUTED_VALUE"""),"Shopping") -> Shopping | D49: =IF(NOT(ISBLANK(B49)), INDIRECT("'Annual Expenses'!D"&B49&":Q"&B49),"") -> 0 | E49: 0 | F49: 0 | G49: 0 | H49: 0 | I49: 0 | J49: 0 | K49: 0 | L49: 0 | M49: 0 | N49: #REF! | O49: #REF! | P49: #REF! | Q49: 0
B50: 10 | C50: =IFERROR(__xludf.DUMMYFUNCTION("""COMPUTED_VALUE"""),"Entertain") -> Entertain | D50: =IF(NOT(ISBLANK(B50)), INDIRECT("'Annual Expenses'!D"&B50&":Q"&B50),"") -> 0 | E50: 0 | F50: 0 | G50: 0 | H50: 0 | I50: 0 | J50: 0 | K50: 0 | L50: 0 | M50: 0 | N50: #REF! | O50: #REF! | P50: #REF! | Q50: 0
B51: 11 | C51: =IFERROR(__xludf.DUMMYFUNCTION("""COMPUTED_VALUE"""),"Home and Laundry") -> Home and Laundry | D51: =IF(NOT(ISBLANK(B51)), INDIRECT("'Annual Expenses'!D"&B51&":Q"&B51),"") -> 0 | E51: 0 | F51: 0 | G51: 0 | H51: 0 | I51: 0 | J51: 0 | K51: 0 | L51: 0 | M51: 0 | N51: #REF! | O51: #REF! | P51: #REF! | Q51: 0
B52: 12 | C52: =IFERROR(__xludf.DUMMYFUNCTION("""COMPUTED_VALUE"""),"Listrik") -> Listrik | D52: =IF(NOT(ISBLANK(B52)), INDIRECT("'Annual Expenses'!D"&B52&":Q"&B52),"") -> 0 | E52: 0 | F52: 0 | G52: 0 | H52: 0 | I52: 0 | J52: 0 | K52: 0 | L52: 0 | M52: 0 | N52: #REF! | O52: #REF! | P52: #REF! | Q52: 0
B53: 13 | C53: =IFERROR(__xludf.DUMMYFUNCTION("""COMPUTED_VALUE"""),"Health/Bodycare") -> Health/Bodycare | D53: =IF(NOT(ISBLANK(B53)), INDIRECT("'Annual Expenses'!D"&B53&":Q"&B53),"") -> 0 | E53: 0 | F53: 0 | G53: 0 | H53: 0 | I53: 0 | J53: 0 | K53: 0 | L53: 0 | M53: 0 | N53: #REF! | O53: #REF! | P53: #REF! | Q53: 0
B54: 14 | C54: =IFERROR(__xludf.DUMMYFUNCTION("""COMPUTED_VALUE"""),"Content dan PP") -> Content dan PP | D54: =IF(NOT(ISBLANK(B54)), INDIRECT("'Annual Expenses'!D"&B54&":Q"&B54),"") -> 0 | E54: 0 | F54: 0 | G54: 0 | H54: 0 | I54: 0 | J54: 0 | K54: 0 | L54: 0 | M54: 0 | N54: #REF! | O54: #REF! | P54: #REF! | Q54: 0
B55: 15 | C55: =IFERROR(__xludf.DUMMYFUNCTION("""COMPUTED_VALUE"""),"Koperasi") -> Koperasi | D55: =IF(NOT(ISBLANK(B55)), INDIRECT("'Annual Expenses'!D"&B55&":Q"&B55),"") -> 0 | E55: 0 | F55: 0 | G55: 0 | H55: 0 | I55: 0 | J55: 0 | K55: 0 | L55: 0 | M55: 0 | N55: #REF! | O55: #REF! | P55: #REF! | Q55: 0
B56: 16 | C56: =IFERROR(__xludf.DUMMYFUNCTION("""COMPUTED_VALUE"""),"Gifts/charity") -> Gifts/charity | D56: =IF(NOT(ISBLANK(B56)), INDIRECT("'Annual Expenses'!D"&B56&":Q"&B56),"") -> 0 | E56: 0 | F56: 0 | G56: 0 | H56: 0 | I56: 0 | J56: 0 | K56: 0 | L56: 0 | M56: 0 | N56: #REF! | O56: #REF! | P56: #REF! | Q56: 0
B57: 17 | C57: =IFERROR(__xludf.DUMMYFUNCTION("""COMPUTED_VALUE"""),"Lending") -> Lending | D57: =IF(NOT(ISBLANK(B57)), INDIRECT("'Annual Expenses'!D"&B57&":Q"&B57),"") -> 0 | E57: 0 | F57: 0 | G57: 0 | H57: 0 | I57: 0 | J57: 0 | K57: 0 | L57: 0 | M57: 0 | N57: #REF! | O57: #REF! | P57: #REF! | Q57: 0
B58: 18 | C58: =IFERROR(__xludf.DUMMYFUNCTION("""COMPUTED_VALUE"""),"SPPD") -> SPPD | D58: =IF(NOT(ISBLANK(B58)), INDIRECT("'Annual Expenses'!D"&B58&":Q"&B58),"") -> 0 | E58: 0 | F58: 0 | G58: 0 | H58: 0 | I58: 0 | J58: 0 | K58: 0 | L58: 0 | M58: 0 | N58: #REF! | O58: #REF! | P58: #REF! | Q58: 0
D59: =IF(NOT(ISBLANK(B59)), INDIRECT("Expenses!D"&B59&":Q"&B59),"")
D60: =IF(NOT(ISBLANK(B60)), INDIRECT("Expenses!D"&B60&":Q"&B60),"")
...

Sheet Annual Expenses
C2: Expenses | D2: 42370 | E2: 42401 | F2: 42430 | G2: 42461 | H2: 42491 | I2: 42522 | J2: 42552 | K2: 42583 | L2: 42614 | M2: 42644 | N2: 42675 | O2: 42705 | P2: Total | Q2: Average
C3: Monthly totals: | D3: =SUM(D4:D18) -> 0 | E3: =SUM(E4:E18) -> 0 | F3: =SUM(F4:F18) -> 0 | G3: =SUM(G4:G18) -> 0 | H3: =SUM(H4:H18) -> 0 | I3: =SUM(I4:I18) -> 0 | J3: =SUM(J4:J18) -> 0 | K3: =SUM(K4:K18) -> 0 | ... O3: =SUM(O4:O18) -> 0 | P3: =SUM(D3:O3) -> 0
A4: =January!B28 -> Food | D4: =January!E28 -> 0 | E4: =February!E28 -> 0 | F4: =March!E28 -> 0 | G4: =April!E28 -> 0 | H4: =Mei!E28 -> 0 | I4: =Juni!E28 -> 0 | J4: =Juli!E28 -> 0 | K4: =Agustus!E28 -> 0 | L4: =September!E28 -> 0 | M4: =Oktober!E28 -> 0 | N4: #REF! | O4: #REF! | P4: =SUM(D4:O4) -> 0 | Q4: =IFERROR(AVERAGE(D4:O4),0) -> 0
A5: =January!B29 -> Groceries | D5: =January!E29 -> 0 | E5: =February!E29 -> 0 | F5: =March!E29 -> 0 | G5: =April!E29 -> 0 | H5: =Mei!E29 -> 0 | I5: =Juni!E29 -> 0 | J5: =Juli!E29 -> 0 | K5: =Agustus!E29 -> 0 | L5: =September!E29 -> 0 | M5: =Oktober!E29 -> 0 | N5: #REF! | O5: #REF! | P5: =SUM(D5:O5) -> 0 | Q5: =IFERROR(AVERAGE(D5:O5),0) -> 0
A6: =January!B30 -> Internet | D6: =January!E30 -> 0 | E6: =February!E30 -> 0 | F6: =March!E30 -> 0 | G6: =April!E30 -> 0 | H6: =Mei!E30 -> 0 | I6: =Juni!E30 -> 0 | J6: =Juli!E30 -> 0 | K6: =Agustus!E30 -> 0 | L6: =September!E30 -> 0 | M6: =Oktober!E30 -> 0 | N6: #REF! | O6: #REF! | P6: =SUM(D6:O6) -> 0 | Q6: =IFERROR(AVERAGE(D6:O6),0) -> 0
A7: =January!B31 -> Kids | D7: =January!E31 -> 0 | E7: =February!E31 -> 0 | F7: =March!E31 -> 0 | G7: =April!E31 -> 0 | H7: =Mei!E31 -> 0 | I7: =Juni!E31 -> 0 | J7: =Juli!E31 -> 0 | K7: =Agustus!E31 -> 0 | L7: =September!E31 -> 0 | M7: =Oktober!E31 -> 0 | N7: #REF! | O7: #REF! | P7: =SUM(D7:O7) -> 0 | Q7: =IFERROR(AVERAGE(D7:O7),0) -> 0
A8: =January!B32 -> Transportation | D8: =January!E32 -> 0 | E8: =February!E32 -> 0 | F8: =March!E32 -> 0 | G8: =April!E32 -> 0 | H8: =Mei!E32 -> 0 | I8: =Juni!E32 -> 0 | J8: =Juli!E32 -> 0 | K8: =Agustus!E32 -> 0 | L8: =September!E32 -> 0 | M8: =Oktober!E32 -> 0 | N8: #REF! | O8: #REF! | P8: =SUM(D8:O8) -> 0 | Q8: =IFERROR(AVERAGE(D8:O8),0) -> 0
A9: =January!B33 -> Shopping | D9: =January!E33 -> 0 | E9: =February!E33 -> 0 | F9: =March!E33 -> 0 | G9: =April!E33 -> 0 | H9: =Mei!E33 -> 0 | I9: =Juni!E33 -> 0 | J9: =Juli!E33 -> 0 | K9: =Agustus!E33 -> 0 | L9: =September!E33 -> 0 | M9: =Oktober!E33 -> 0 | N9: #REF! | O9: #REF! | P9: =SUM(D9:O9) -> 0 | Q9: =IFERROR(AVERAGE(D9:O9),0) -> 0
A10: =January!B34 -> Entertain | D10: =January!E34 -> 0 | E10: =February!E34 -> 0 | F10: =March!E34 -> 0 | G10: =April!E34 -> 0 | H10: =Mei!E34 -> 0 | I10: =Juni!E34 -> 0 | J10: =Juli!E34 -> 0 | K10: =Agustus!E34 -> 0 | L10: =September!E34 -> 0 | M10: =Oktober!E34 -> 0 | N10: #REF! | O10: #REF! | P10: =SUM(D10:O10) -> 0 | Q10: =IFERROR(AVERAGE(D10:O10),0) -> 0
A11: =January!B35 -> Home and Laundry | D11: =January!E35 -> 0 | E11: =February!E35 -> 0 | F11: =March!E35 -> 0 | G11: =April!E35 -> 0 | H11: =Mei!E35 -> 0 | I11: =Juni!E35 -> 0 | J11: =Juli!E35 -> 0 | K11: =Agustus!E35 -> 0 | L11: =September!E35 -> 0 | M11: =Oktober!E35 -> 0 | N11: #REF! | O11: #REF! | P11: =SUM(D11:O11) -> 0 | Q11: =IFERROR(AVERAGE(D11:O11),0) -> 0
A12: =January!B36 -> Listrik | D12: =January!E36 -> 0 | E12: =February!E36 -> 0 | F12: =March!E36 -> 0 | G12: =April!E36 -> 0 | H12: =Mei!E36 -> 0 | I12: =Juni!E36 -> 0 | J12: =Juli!E36 -> 0 | K12: =Agustus!E36 -> 0 | L12: =September!E36 -> 0 | M12: =Oktober!E36 -> 0 | N12: #REF! | O12: #REF! | P12: =SUM(D12:O12) -> 0 | Q12: =IFERROR(AVERAGE(D12:O12),0) -> 0
A13: =January!B37 -> Health/Bodycare | D13: =January!E37 -> 0 | E13: =February!E37 -> 0 | F13: =March!E37 -> 0 | G13: =April!E37 -> 0 | H13: =Mei!E37 -> 0 | I13: =Juni!E37 -> 0 | J13: =Juli!E37 -> 0 | K13: =Agustus!E37 -> 0 | L13: =September!E37 -> 0 | M13: =Oktober!E37 -> 0 | N13: #REF! | O13: #REF! | P13: =SUM(D13:O13) -> 0 | Q13: =IFERROR(AVERAGE(D13:O13),0) -> 0
A14: =January!B38 -> Content dan PP | D14: =January!E38 -> 0 | E14: =February!E38 -> 0 | F14: =March!E38 -> 0 | G14: =April!E38 -> 0 | H14: =Mei!E38 -> 0 | I14: =Juni!E38 -> 0 | J14: =Juli!E38 -> 0 | K14: =Agustus!E38 -> 0 | L14: =September!E38 -> 0 | M14: =Oktober!E38 -> 0 | N14: #REF! | O14: #REF! | P14: =SUM(D14:O14) -> 0 | Q14: =IFERROR(AVERAGE(D14:O14),0) -> 0
A15: =January!B39 -> Koperasi | D15: =January!E39 -> 0 | E15: =February!E39 -> 0 | F15: =March!E39 -> 0 | G15: =April!E39 -> 0 | H15: =Mei!E39 -> 0 | I15: =Juni!E39 -> 0 | J15: =Juli!E39 -> 0 | K15: =Agustus!E39 -> 0 | L15: =September!E39 -> 0 | M15: =Oktober!E39 -> 0 | N15: #REF! | O15: #REF! | P15: =SUM(D15:O15) -> 0 | Q15: =IFERROR(AVERAGE(D15:O15),0) -> 0
... A18: =January!B42 -> SPPD | D18: =January!E42 -> 0 | E18: =February!E42 -> 0 | F18: =March!E42 -> 0 | G18: =April!E42 -> 0 | H18: =Mei!E42 -> 0 | I18: =Juni!E42 -> 0 | J18: =Juli!E42 -> 0 | K18: =Agustus!E42 -> 0 | L18: =September!E42 -> 0 | M18: =Oktober!E42 -> 0 | N18: #REF! | O18: #REF! | P18: =SUM(D18:O18) -> 0 | Q18: =IFERROR(AVERAGE(D18:O18),0) -> 0
A19: =January!B43 -> 0 | D19: =January!E43 -> 0 | E19: =February!E43 -> 0 | F19: =March!E43 -> 0 | G19: =April!E43 -> 0 | H19: =Mei!E43 -> 0 | J19: =Juli!E43 -> 0
A20: =January!B44 -> 0 | D20: =January!E43 -> 0 | E20: =February!E44 | F20: =March!E44 | G20: =April!E44

Sheet Annual Income
C2: Income | D2: 42370 | E2: 42401 | F2: 42430 | G2: 42461 | H2: 42491 | I2: 42522 | J2: 42552 | K2: 42583 | L2: 42614 | M2: 42644 | N2: 42675 | O2: 42705 | P2: Total | Q2: Average
C3: Monthly totals: | D3: =SUM(D4:D10) -> 0 | E3: =SUM(E4:E10) -> 0 | F3: =SUM(F4:F10) -> 0 | G3: =SUM(G4:G10) -> 0 | H3: =SUM(H4:H10) -> 0 | I3: =SUM(I4:I10) -> 0 | J3: =SUM(J4:J10) -> 0 | K3: =SUM(K4:K10) -> 0 | ... O3: =SUM(O4:O10) -> 0 | P3: =SUM(D3:O3) -> 0
A4: =January!H28 -> Savings | D4: =January!K28 -> 0 | E4: =February!K28 -> 0 | F4: =March!K28 -> 0 | G4: =April!K28 -> 0 | H4: =Mei!K28 -> 0 | I4: =Juni!K28 -> 0 | J4: =Juli!K28 -> 0 | K4: =Agustus!K28 -> 0 | L4: =September!K28 -> 0 | M4: =Oktober!K28 -> 0 | N4: #REF! | O4: #REF! | P4: =SUM(D4:O4) -> 0 | Q4: =IFERROR(AVERAGE(D4:O4),0) -> 0
A5: =January!H29 -> Paycheck | D5: =January!K29 -> 0 | E5: =February!K29 -> 0 | F5: =March!K29 -> 0 | G5: =April!K29 -> 0 | H5: =Mei!K29 -> 0 | I5: =Juni!K29 -> 0 | J5: =Juli!K29 -> 0 | K5: =Agustus!K29 -> 0 | L5: =September!K29 -> 0 | M5: =Oktober!K29 -> 0 | N5: #REF! | O5: #REF! | P5: =SUM(D5:O5) -> 0 | Q5: =IFERROR(AVERAGE(D5:O5),0) -> 0
A6: =January!H30 -> Bonus | D6: =January!K30 -> 0 | E6: =February!K30 -> 0 | F6: =March!K30 -> 0 | G6: =April!K30 -> 0 | H6: =Mei!K30 -> 0 | I6: =Juni!K30 -> 0 | J6: =Juli!K30 -> 0 | K6: =Agustus!K30 -> 0 | L6: =September!K30 -> 0 | M6: =Oktober!K30 -> 0 | N6: #REF! | O6: #REF! | P6: =SUM(D6:O6) -> 0 | Q6: =IFERROR(AVERAGE(D6:O6),0) -> 0
A7: =January!H31 -> Interest | D7: =January!K31 -> 0 | E7: =February!K31 -> 0 | F7: =March!K31 -> 0 | G7: =April!K31 -> 0 | H7: =Mei!K31 -> 0 | I7: =Juni!K31 -> 0 | J7: =Juli!K31 -> 0 | K7: =Agustus!K31 -> 0 | L7: =September!K31 -> 0 | M7: =Oktober!K31 -> 0 | N7: #REF! | O7: #REF! | P7: =SUM(D7:O7) -> 0 | Q7: =IFERROR(AVERAGE(D7:O7),0) -> 0
A8: =January!H32 -> Affiliate | D8: =January!K32 -> 0 | E8: =February!K32 -> 0 | F8: =March!K32 -> 0 | G8: =April!K32 -> 0 | H8: =Mei!K32 -> 0 | I8: =Juni!K32 -> 0 | J8: =Juli!K32 -> 0 | K8: =Agustus!K32 -> 0 | L8: =September!K32 -> 0 | M8: =Oktober!K32 -> 0 | N8: #REF! | O8: #REF! | P8: =SUM(D8:O8) -> 0 | Q8: =IFERROR(AVERAGE(D8:O8),0) -> 0
A9: =January!H33 -> IKS | D9: =January!K33 -> 0 | E9: =February!K33 -> 0 | F9: =March!K33 -> 0 | G9: =April!K33 -> 0 | H9: =Mei!K33 -> 0 | I9: =Juni!K33 -> 0 | J9: =Juli!K33 -> 0 | K9: =Agustus!K33 -> 0 | L9: =September!K33 -> 0 | M9: =Oktober!K33 -> 0 | N9: #REF! | O9: #REF! | P9: =SUM(D9:O9) -> 0 | Q9: =IFERROR(AVERAGE(D9:O9),0) -> 0
A10: =January!H34 -> Endorsement | D10: =January!K34 -> 0 | E10: =February!K34 -> 0 | F10: =March!K34 -> 0 | G10: =April!K34 -> 0 | H10: =Mei!K34 -> 0 | I10: =Juni!K34 -> 0 | J10: =Juli!K34 -> 0 | K10: =Agustus!K34 -> 0 | L10: =September!K34 -> 0 | M10: =Oktober!K34 -> 0 | N10: #REF! | O10: #REF! | P10: =SUM(D10:O10) -> 0 | Q10: =IFERROR(AVERAGE(D10:O10),0) -> 0
A11: =January!H35 -> 0 | E11: =February!K35 | F11: =March!K35 | G11: =April!K35 | H11: =Mei!K35 | I11: =Juni!K35 | J11: =Juli!K35 | K11: =Agustus!K35 | L11: =September!K35 | M11: =Oktober!K35 | N11: #REF!

Sheet Deskripsi
A1: Food | B1: maksi | C1: =50000*31 -> 1550000 | D1: =C4/20 -> 32075 | G1: 6044094 | H1: food | I1: =G1/11*12 -> 6593557.1
B2: makan malam | C2: =180000*31 -> 5580000 | G2: 705600 | H2: groceries | I2: =G2/11*12 -> 769745.45
A3: =SUM(C1:C2) -> 7130000 | I3: =SUM(I1:I2) -> 7363302.5
B4: titipku | C4: =241500+400000 -> 641500 | G4: 519092 | H4: internet | I4: =G4/11*12 -> 566282.18
B5: mart | C5: =B6-C4 -> 108500
A6: Groceries | B6: =750000 -> 750000
A11: Internet
A12: Bensin | C12: =350000*4 -> 1400000
A15: laundry | B15: =40000*4 -> 160000
A16: transport | B16: =350000*4 -> 1400000

Sheet January
B2: GET STARTED | I2: NOTE
B3: Set your starting balance in cell L8, then customize your categories and planned spending amounts in the 'Income' and 'Expenses' tables below. | I3: Only edit highlighted cells.
I4: Try not to alter cells that contain a formula.
B5: As you enter data in the 'Transactions' tab, this sheet will automatically update to show a summary of your spending for the month.
B8: Monthly Budget 2024 | J8: Starting balance: | L8: 3000000
D12: =IFERROR(__xludf.DUMMYFUNCTION("SPARKLINE(D17,{""charttype"",""column"";""ymin"", 0; ""ymax"",MAX(D17:E17);""firstcolor"",""#334960""})"),"") | E12: =IFERROR(__xludf.DUMMYFUNCTION("SPARKLINE(E17,{""charttype"",""column"";""ymin"", 0; ""ymax"",max(D17:E17);""firstcolor"",""#f46524""})"),"")
H13: =IFERROR(E17/D17-1, "") -> 0
H14: =IF(H13 < 0, "Decrease in total savings", "Increase in total savings") -> Increase in total savings
H15: =IFERROR(E17-D17, 0) -> 0
D16: START BALANCE | E16: END BALANCE | H16: =IF(J15<0, "Spent this month", "Saved this month") -> Saved this month
D17: =IF(ISBLANK(L8),0,L8) -> 3000000 | E17: =D17+(I22-C22) -> 3000000
B20: Expenses | H20: Income
B21: Planned | C21: =D26 -> 2030000 | D21: =IFERROR(__xludf.DUMMYFUNCTION("SPARKLINE(C21,{""charttype"",""bar"";""max"",max(C21:C22);""color1"",""#AEB7C0""})"),"") | H21: Planned | I21: =J26 -> 300000 | J21: =IFERROR(__xludf.DUMMYFUNCTION("SPARKLINE(I21,{""charttype"",""bar"";""max"",max(I21:I22);""color1"",""#AEB7C0""})"),"")
B22: Actual | C22: =E26 -> 0 | D22: =IFERROR(__xludf.DUMMYFUNCTION("SPARKLINE(C22,{""charttype"",""bar"";""max"",max(C21:C22);""color1"",""#334960""})"),"") | H22: Actual | I22: =K26 -> 0 | J22: =IFERROR(__xludf.DUMMYFUNCTION("SPARKLINE(I22,{""charttype"",""bar"";""max"",max(I21:I22);""color1"",""#334960""})"),"")
B24: Expenses | H24: Income
D25: Planned | E25: Actual | F25: Diff. | J25: Planned | K25: Actual | L25: Diff.
B26: Totals | D26: =SUM(D27:D1044) -> 2030000 | E26: =SUM(E27:E1044) -> 0 | F26: =SUM(F27:F1044) -> 2030000 | H26: Totals | J26: =SUM(J27:J44) -> 300000 | K26: =SUM(K27:K44) -> 0 | L26: =SUM(L27:L44) -> -300000
E27: =IF(ISBLANK($B27), "", SUMIF('Trans Jan'!$E:$E,$B27,'Trans Jan'!$C:$C)) | F27: =IF(ISBLANK($B27), "", D27-E27) | K27: =IF(ISBLANK($H27), "", SUMIF('Trans Jan'!$J:$J,$H27,'Trans Jan'!$H:$H)) | L27: =IF(ISBLANK($H27), "", K27-J27)
B28: Food | D28: 1000000 | E28: =IF(ISBLANK($B28), "", SUMIF('Trans Jan'!$E:$E,$B28,'Trans Jan'!$C:$C)) -> 0 | F28: =IF(ISBLANK($B28), "", D28-E28) -> 1000000 | H28: Savings | J28: 300000 | K28: =IF(ISBLANK($H28), "", SUMIF('Trans Jan'!$J:$J,$H28,'Trans Jan'!$H:$H)) -> 0 | L28: =IF(ISBLANK($H28), "", K28-J28) -> -300000
B29: Groceries | D29: 0 | E29: =IF(ISBLANK($B29), "", SUMIF('Trans Jan'!$E:$E,$B29,'Trans Jan'!$C:$C)) -> 0 | F29: =IF(ISBLANK($B29), "", D29-E29) -> 0 | H29: Paycheck | J29: 0 | K29: =IF(ISBLANK($H29), "", SUMIF('Trans Jan'!$J:$J,$H29,'Trans Jan'!$H:$H)) -> 0 | L29: =IF(ISBLANK($H29), "", K29-J29) -> 0
B30: Internet | D30: 30000 | E30: =IF(ISBLANK($B30), "", SUMIF('Trans Jan'!$E:$E,$B30,'Trans Jan'!$C:$C)) -> 0 | F30: =IF(ISBLANK($B30), "", D30-E30) -> 30000 | H30: Bonus | J30: 0 | K30: =IF(ISBLANK($H30), "", SUMIF('Trans Jan'!$J:$J,$H30,'Trans Jan'!$H:$H)) -> 0 | L30: =IF(ISBLANK($H30), "", K30-J30) -> 0
B31: Kids | D31: 0 | E31: =IF(ISBLANK($B31), "", SUMIF('Trans Jan'!$E:$E,$B31,'Trans Jan'!$C:$C)) -> 0 | F31: =IF(ISBLANK($B31), "", D31-E31) -> 0 | H31: Interest | J31: 0 | K31: =IF(ISBLANK($H31), "", SUMIF('Trans Jan'!$J:$J,$H31,'Trans Jan'!$H:$H)) -> 0 | L31: =IF(ISBLANK($H31), "", K31-J31) -> 0
B32: Transportation | D32: 200000 | E32: =IF(ISBLANK($B32), "", SUMIF('Trans Jan'!$E:$E,$B32,'Trans Jan'!$C:$C)) -> 0 | F32: =IF(ISBLANK($B32), "", D32-E32) -> 200000 | H32: Affiliate | J32: 0 | K32: =IF(ISBLANK($H32), "", SUMIF('Trans Jan'!$J:$J,$H32,'Trans Jan'!$H:$H)) -> 0 | L32: =IF(ISBLANK($H32), "", K32-J32) -> 0
B33: Shopping | D33: 0 | E33: =IF(ISBLANK($B33), "", SUMIF('Trans Jan'!$E:$E,$B33,'Trans Jan'!$C:$C)) -> 0 | F33: =IF(ISBLANK($B33), "", D33-E33) -> 0 | H33: IKS | J33: 0 | K33: =IF(ISBLANK($H33), "", SUMIF('Trans Jan'!$J:$J,$H33,'Trans Jan'!$H:$H)) -> 0 | L33: =IF(ISBLANK($H33), "", K33-J33) -> 0
B34: Entertain | D34: 0 | E34: =IF(ISBLANK($B34), "", SUMIF('Trans Jan'!$E:$E,$B34,'Trans Jan'!$C:$C)) -> 0 | F34: =IF(ISBLANK($B34), "", D34-E34) -> 0 | H34: Endorsement | J34: 0 | K34: =IF(ISBLANK($H34), "", SUMIF('Trans Jan'!$J:$J,$H34,'Trans Jan'!$H:$H)) -> 0 | L34: =IF(ISBLANK($H34), "", K34-J34) -> 0
B35: Home and Laundry | D35: 800000 | E35: =IF(ISBLANK($B35), "", SUMIF('Trans Jan'!$E:$E,$B35,'Trans Jan'!$C:$C)) -> 0 | F35: =IF(ISBLANK($B35), "", D35-E35) -> 800000 | K35: =IF(ISBLANK($H35), "", SUMIF('Trans Jan'!$J:$J,$H35,'Trans Jan'!$H:$H)) | L35: =IF(ISBLANK($H35), "", K35-J35)
B36: Listrik | D36: 0 | E36: =IF(ISBLANK($B36), "", SUMIF('Trans Jan'!$E:$E,$B36,'Trans Jan'!$C:$C)) -> 0 | F36: =IF(ISBLANK($B36), "", D36-E36) -> 0 | K36: =IF(ISBLANK($H36), "", SUMIF('Trans Jan'!$J:$J,$H36,'Trans Jan'!$H:$H)) | L36: =IF(ISBLANK($H36), "", K36-J36)
B37: Health/Bodycare | D37: 0 | E37: =IF(ISBLANK($B37), "", SUMIF('Trans Jan'!$E:$E,$B37,'Trans Jan'!$C:$C)) -> 0 | F37: =IF(ISBLANK($B37), "", D37-E37) -> 0 | K37: =IF(ISBLANK($H37), "", SUMIF('Trans Jan'!$J:$J,$H37,'Trans Jan'!$H:$H)) | L37: =IF(ISBLANK($H37), "", K37-J37)
B38: Content dan PP | D38: 0 | E38: =IF(ISBLANK($B38), "", SUMIF('Trans Jan'!$E:$E,$B38,'Trans Jan'!$C:$C)) -> 0 | F38: =IF(ISBLANK($B38), "", D38-E38) -> 0 | K38: =IF(ISBLANK($H38), "", SUMIF('Trans Jan'!$J:$J,$H38,'Trans Jan'!$H:$H)) | L38: =IF(ISBLANK($H38), "", K38-J38)
B39: Koperasi | D39: 0 | E39: =IF(ISBLANK($B39), "", SUMIF('Trans Jan'!$E:$E,$B39,'Trans Jan'!$C:$C)) -> 0 | F39: =IF(ISBLANK($B39), "", D39-E39) -> 0 | K39: =IF(ISBLANK($H39), "", SUMIF('Trans Jan'!$J:$J,$H39,'Trans Jan'!$H:$H)) | L39: =IF(ISBLANK($H39), "", K39-J39)
B40: Gifts/charity | D40: 0 | E40: =IF(ISBLANK($B40), "", SUMIF('Trans Jan'!$E:$E,$B40,'Trans Jan'!$C:$C)) -> 0 | F40: =IF(ISBLANK($B40), "", D40-E40) -> 0 | K40: =IF(ISBLANK($H40), "", SUMIF('Trans Jan'!$J:$J,$H40,'Trans Jan'!$H:$H)) | L40: =IF(ISBLANK($H40), "", K40-J40)
B41: Lending | D41: 0 | E41: =IF(ISBLANK($B41), "", SUMIF('Trans Jan'!$E:$E,$B41,'Trans Jan'!$C:$C)) -> 0 | F41: =IF(ISBLANK($B41), "", D41-E41) -> 0 | K41: =IF(ISBLANK($H41), "", SUMIF('Trans Jan'!$J:$J,$H41,'Trans Jan'!$H:$H)) | L41: =IF(ISBLANK($H41), "", K41-J41)
B42: SPPD | D42: 0 | E42: =IF(ISBLANK($B42), "", SUMIF('Trans Jan'!$E:$E,$B42,'Trans Jan'!$C:$C)) -> 0 | F42: =IF(ISBLANK($B42), "", D42-E42) -> 0 | K42: =IF(ISBLANK($H42), "", SUMIF('Trans Jan'!$J:$J,$H42,'Trans Jan'!$H:$H)) | L42: =IF(ISBLANK($H42), "", K42-J42)
F43: =IF(ISBLANK($B43), "", D43-E43) | K43: =IF(ISBLANK($H43), "", SUMIF('Trans Jan'!$J:$J,$H43,'Trans Jan'!$H:$H)) | L43: =IF(ISBLANK($H43), "", K43-J43)
E44: =IF(ISBLANK($B44), "", SUMIF('Trans Jan'!$E:$E,$B44,'Trans Jan'!$C:$C)) | K44: =IF(ISBLANK($H44), "", SUMIF('Trans Jan'!$J:$J,$H44,'Trans Jan'!$H:$H)) | L44: =IF(ISBLANK($H44), "", K44-J44)

Sheet Trans Jan
B1: Change or add categories by updating the Expenses and Income tables in the Summary sheet.
B2: Expenses | G2: Income
B4: Date | C4: Amount | D4: Description | E4: Category | G4: Date | H4: Amount | I4: Description | J4: Category

Sheet February
B2: GET STARTED | I2: NOTE
B3: Set your starting balance in cell L8, then customize your categories and planned spending amounts in the 'Income' and 'Expenses' tables below. | I3: Only edit highlighted cells.
I4: Try not to alter cells that contain a formula.
B5: As you enter data in the 'Transactions' tab, this sheet will automatically update to show a summary of your spending for the month.
B8: Monthly Budget | J8: Starting balance: | L8: =January!E17 -> 3000000
D12: =IFERROR(__xludf.DUMMYFUNCTION("SPARKLINE(D17,{""charttype"",""column"";""ymin"", 0; ""ymax"",MAX(D17:E17);""firstcolor"",""#334960""})"),"") | E12: =IFERROR(__xludf.DUMMYFUNCTION("SPARKLINE(E17,{""charttype"",""column"";""ymin"", 0; ""ymax"",max(D17:E17);""firstcolor"",""#f46524""})"),"")
I13: =IFERROR(E17/D17-1, "") -> 0
I14: =IF(I13 < 0, "Decrease in total savings", "Increase in total savings") -> Increase in total savings
I15: =IFERROR(E17-D17, 0) -> 0
D16: START BALANCE | E16: END BALANCE | I16: =IF(J15<0, "Spent this month", "Saved this month") -> Saved this month
D17: =IF(ISBLANK(L8),0,L8) -> 3000000 | E17: =D17+(I22-C22) -> 3000000
B20: Expenses | H20: Income
B21: Planned | C21: =D26 -> 22450000 | D21: =IFERROR(__xludf.DUMMYFUNCTION("SPARKLINE(C21,{""charttype"",""bar"";""max"",max(C21:C22);""color1"",""#AEB7C0""})"),"") | H21: Planned | I21: =J26 -> 0 | J21: =IFERROR(__xludf.DUMMYFUNCTION("SPARKLINE(I21,{""charttype"",""bar"";""max"",max(I21:I22);""color1"",""#AEB7C0""})"),"")
B22: Actual | C22: =E26 -> 0 | D22: =IFERROR(__xludf.DUMMYFUNCTION("SPARKLINE(C22,{""charttype"",""bar"";""max"",max(C21:C22);""color1"",""#334960""})"),"") | H22: Actual | I22: =K26 -> 0 | J22: =IFERROR(__xludf.DUMMYFUNCTION("SPARKLINE(I22,{""charttype"",""bar"";""max"",max(I21:I22);""color1"",""#334960""})"),"")
B24: Expenses | H24: Income
D25: Planned | E25: Actual | F25: Diff. | J25: Planned | K25: Actual | L25: Diff.
B26: Totals | D26: =SUM(D27:D1044) -> 22450000 | E26: =SUM(E27:E1044) -> 0 | F26: =SUM(F27:F1044) -> 22450000 | H26: Totals | J26: =SUM(J27:J44) -> 0 | K26: =SUM(K27:K44) -> 0 | L26: =SUM(L27:L44) -> 0
E27: =IF(ISBLANK($B27), "", SUMIF('Trans Feb'!$E:$E,$B27,'Trans Feb'!$C:$C)) | F27: =IF(ISBLANK($B27), "", D27-E27) | K27: =IF(ISBLANK($H27), "", SUMIF('Trans Feb'!$J:$J,$H27,'Trans Feb'!$H:$H)) | L27: =IF(ISBLANK($H27), "", K27-J27)
B28: Food | D28: 7000000 | E28: =IF(ISBLANK($B28), "", SUMIF('Trans Feb'!$E:$E,$B28,'Trans Feb'!$C:$C)) -> 0 | F28: =IF(ISBLANK($B28), "", D28-E28) -> 7000000 | H28: Savings | K28: =IF(ISBLANK($H28), "", SUMIF('Trans Feb'!$J:$J,$H28,'Trans Feb'!$H:$H)) -> 0 | L28: =IF(ISBLANK($H28), "", K28-J28) -> 0
B29: Groceries | D29: 500000 | E29: =IF(ISBLANK($B29), "", SUMIF('Trans Feb'!$E:$E,$B29,'Trans Feb'!$C:$C)) -> 0 | F29: =IF(ISBLANK($B29), "", D29-E29) -> 500000 | H29: Paycheck | K29: =IF(ISBLANK($H29), "", SUMIF('Trans Feb'!$J:$J,$H29,'Trans Feb'!$H:$H)) -> 0 | L29: =IF(ISBLANK($H29), "", K29-J29) -> 0
B30: Internet | D30: 600000 | E30: =IF(ISBLANK($B30), "", SUMIF('Trans Feb'!$E:$E,$B30,'Trans Feb'!$C:$C)) -> 0 | F30: =IF(ISBLANK($B30), "", D30-E30) -> 600000 | H30: Bonus | K30: =IF(ISBLANK($H30), "", SUMIF('Trans Feb'!$J:$J,$H30,'Trans Feb'!$H:$H)) -> 0 | L30: =IF(ISBLANK($H30), "", K30-J30) -> 0
B31: Kids | D31: 5000000 | E31: =IF(ISBLANK($B31), "", SUMIF('Trans Feb'!$E:$E,$B31,'Trans Feb'!$C:$C)) -> 0 | F31: =IF(ISBLANK($B31), "", D31-E31) -> 5000000 | H31: Interest | K31: =IF(ISBLANK($H31), "", SUMIF('Trans Feb'!$J:$J,$H31,'Trans Feb'!$H:$H)) -> 0 | L31: =IF(ISBLANK($H31), "", K31-J31) -> 0
B32: Transportation | D32: 4000000 | E32: =IF(ISBLANK($B32), "", SUMIF('Trans Feb'!$E:$E,$B32,'Trans Feb'!$C:$C)) -> 0 | F32: =IF(ISBLANK($B32), "", D32-E32) -> 4000000 | H32: Affiliate | K32: =IF(ISBLANK($H32), "", SUMIF('Trans Feb'!$J:$J,$H32,'Trans Feb'!$H:$H)) -> 0 | L32: =IF(ISBLANK($H32), "", K32-J32) -> 0
B33: Shopping | D33: 1500000 | E33: =IF(ISBLANK($B33), "", SUMIF('Trans Feb'!$E:$E,$B33,'Trans Feb'!$C:$C)) -> 0 | F33: =IF(ISBLANK($B33), "", D33-E33) -> 1500000 | H33: IKS | K33: =IF(ISBLANK($H33), "", SUMIF('Trans Feb'!$J:$J,$H33,'Trans Feb'!$H:$H)) -> 0 | L33: =IF(ISBLANK($H33), "", K33-J33) -> 0
B34: Entertain | D34: 500000 | E34: =IF(ISBLANK($B34), "", SUMIF('Trans Feb'!$E:$E,$B34,'Trans Feb'!$C:$C)) -> 0 | F34: =IF(ISBLANK($B34), "", D34-E34) -> 500000 | H34: Endorsement | K34: =IF(ISBLANK($H34), "", SUMIF('Trans Feb'!$J:$J,$H34,'Trans Feb'!$H:$H)) -> 0 | L34: =IF(ISBLANK($H34), "", K34-J34) -> 0
B35: Home and Laundry | D35: 500000 | E35: =IF(ISBLANK($B35), "", SUMIF('Trans Feb'!$E:$E,$B35,'Trans Feb'!$C:$C)) -> 0 | F35: =IF(ISBLANK($B35), "", D35-E35) -> 500000 | K35: =IF(ISBLANK($H35), "", SUMIF('Trans Feb'!$J:$J,$H35,'Trans Feb'!$H:$H)) | L35: =IF(ISBLANK($H35), "", K35-J35)
B36: Listrik | D36: 500000 | E36: =IF(ISBLANK($B36), "", SUMIF('Trans Feb'!$E:$E,$B36,'Trans Feb'!$C:$C)) -> 0 | F36: =IF(ISBLANK($B36), "", D36-E36) -> 500000 | K36: =IF(ISBLANK($H36), "", SUMIF('Trans Feb'!$J:$J,$H36,'Trans Feb'!$H:$H)) | L36: =IF(ISBLANK($H36), "", K36-J36)
B37: Health/Bodycare | D37: 500000 | E37: =IF(ISBLANK($B37), "", SUMIF('Trans Feb'!$E:$E,$B37,'Trans Feb'!$C:$C)) -> 0 | F37: =IF(ISBLANK($B37), "", D37-E37) -> 500000 | K37: =IF(ISBLANK($H37), "", SUMIF('Trans Feb'!$J:$J,$H37,'Trans Feb'!$H:$H)) | L37: =IF(ISBLANK($H37), "", K37-J37)
B38: Content dan PP | D38: 200000 | E38: =IF(ISBLANK($B38), "", SUMIF('Trans Feb'!$E:$E,$B38,'Trans Feb'!$C:$C)) -> 0 | F38: =IF(ISBLANK($B38), "", D38-E38) -> 200000 | K38: =IF(ISBLANK($H38), "", SUMIF('Trans Feb'!$J:$J,$H38,'Trans Feb'!$H:$H)) | L38: =IF(ISBLANK($H38), "", K38-J38)
B39: Koperasi | D39: 150000 | E39: =IF(ISBLANK($B39), "", SUMIF('Trans Feb'!$E:$E,$B39,'Trans Feb'!$C:$C)) -> 0 | F39: =IF(ISBLANK($B39), "", D39-E39) -> 150000 | K39: =IF(ISBLANK($H39), "", SUMIF('Trans Feb'!$J:$J,$H39,'Trans Feb'!$H:$H)) | L39: =IF(ISBLANK($H39), "", K39-J39)
B40: Gifts/charity | D40: 1500000 | E40: =IF(ISBLANK($B40), "", SUMIF('Trans Feb'!$E:$E,$B40,'Trans Feb'!$C:$C)) -> 0 | F40: =IF(ISBLANK($B40), "", D40-E40) -> 1500000 | K40: =IF(ISBLANK($H40), "", SUMIF('Trans Feb'!$J:$J,$H40,'Trans Feb'!$H:$H)) | L40: =IF(ISBLANK($H40), "", K40-J40)
B41: Lending | D41: 0 | E41: =IF(ISBLANK($B41), "", SUMIF('Trans Feb'!$E:$E,$B41,'Trans Feb'!$C:$C)) -> 0 | F41: =IF(ISBLANK($B41), "", D41-E41) -> 0 | K41: =IF(ISBLANK($H41), "", SUMIF('Trans Feb'!$J:$J,$H41,'Trans Feb'!$H:$H)) | L41: =IF(ISBLANK($H41), "", K41-J41)
B42: SPPD | D42: 0 | E42: =IF(ISBLANK($B42), "", SUMIF('Trans Feb'!$E:$E,$B42,'Trans Feb'!$C:$C)) -> 0 | F42: =IF(ISBLANK($B42), "", D42-E42) -> 0 | K42: =IF(ISBLANK($H42), "", SUMIF('Trans Feb'!$J:$J,$H42,'Trans Feb'!$H:$H)) | L42: =IF(ISBLANK($H42), "", K42-J42)
F43: =IF(ISBLANK($B43), "", D43-E43) | K43: =IF(ISBLANK($H43), "", SUMIF('Trans Feb'!$J:$J,$H43,'Trans Feb'!$H:$H)) | L43: =IF(ISBLANK($H43), "", K43-J43)
E44: =IF(ISBLANK($B44), "", SUMIF('Trans Feb'!$E:$E,$B44,'Trans Feb'!$C:$C)) | K44: =IF(ISBLANK($H44), "", SUMIF('Trans Feb'!$J:$J,$H44,'Trans Feb'!$H:$H)) | L44: =IF(ISBLANK($H44), "", K44-J44)

Sheet Trans Feb
B1: Change or add categories by updating the Expenses and Income tables in the Summary sheet.
B2: Expenses | G2: Income
B4: Date | C4: Amount | D4: Description | E4: Category | G4: Date | H4: Amount | I4: Description | J4: Category

Sheet March
B2: GET STARTED | I2: NOTE
B3: Set your starting balance in cell L8, then customize your categories and planned spending amounts in the 'Income' and 'Expenses' tables below. | I3: Only edit highlighted cells.
I4: Try not to alter cells that contain a formula.
B5: As you enter data in the 'Transactions' tab, this sheet will automatically update to show a summary of your spending for the month.
B8: Monthly Budget | J8: Starting balance: | L8: =February!E17 -> 3000000
D12: =IFERROR(__xludf.DUMMYFUNCTION("SPARKLINE(D17,{""charttype"",""column"";""ymin"", 0; ""ymax"",MAX(D17:E17);""firstcolor"",""#334960""})"),"") | E12: =IFERROR(__xludf.DUMMYFUNCTION("SPARKLINE(E17,{""charttype"",""column"";""ymin"", 0; ""ymax"",max(D17:E17);""firstcolor"",""#f46524""})"),"")
I13: =IFERROR(E17/D17-1, "") -> 0
I14: =IF(I13 < 0, "Decrease in total savings", "Increase in total savings") -> Increase in total savings
I15: =IFERROR(E17-D17, 0) -> 0
D16: START BALANCE | E16: END BALANCE | I16: =IF(J15<0, "Spent this month", "Saved this month") -> Saved this month
D17: =IF(ISBLANK(L8),0,L8) -> 3000000 | E17: =D17+(I22-C22) -> 3000000
B20: Expenses | H20: Income
B21: Planned | C21: =D26 -> 22450000 | D21: =IFERROR(__xludf.DUMMYFUNCTION("SPARKLINE(C21,{""charttype"",""bar"";""max"",max(C21:C22);""color1"",""#AEB7C0""})"),"") | H21: Planned | I21: =J26 -> 0 | J21: =IFERROR(__xludf.DUMMYFUNCTION("SPARKLINE(I21,{""charttype"",""bar"";""max"",max(I21:I22);""color1"",""#AEB7C0""})"),"")
B22: Actual | C22: =E26 -> 0 | D22: =IFERROR(__xludf.DUMMYFUNCTION("SPARKLINE(C22,{""charttype"",""bar"";""max"",max(C21:C22);""color1"",""#334960""})"),"") | H22: Actual | I22: =K26 -> 0 | J22: =IFERROR(__xludf.DUMMYFUNCTION("SPARKLINE(I22,{""charttype"",""bar"";""max"",max(I21:I22);""color1"",""#334960""})"),"")
B24: Expenses | H24: Income
D25: Planned | E25: Actual | F25: Diff. | J25: Planned | K25: Actual | L25: Diff.
B26: Totals | D26: =SUM(D27:D1044) -> 22450000 | E26: =SUM(E27:E1044) -> 0 | F26: =SUM(F27:F1044) -> 22450000 | H26: Totals | J26: =SUM(J27:J44) -> 0 | K26: =SUM(K27:K44) -> 0 | L26: =SUM(L27:L44) -> 0
E27: =IF(ISBLANK($B27), "", SUMIF('Trans March'!$E:$E,$B27,'Trans March'!$C:$C)) | F27: =IF(ISBLANK($B27), "", D27-E27) | K27: =IF(ISBLANK($H27), "", SUMIF('Trans March'!$J:$J,$H27,'Trans March'!$H:$H)) | L27: =IF(ISBLANK($H27), "", K27-J27)
B28: Food | D28: 7000000 | E28: =IF(ISBLANK($B28), "", SUMIF('Trans March'!$E:$E,$B28,'Trans March'!$C:$C)) -> 0 | F28: =IF(ISBLANK($B28), "", D28-E28) -> 7000000 | H28: Savings | K28: =IF(ISBLANK($H28), "", SUMIF('Trans March'!$J:$J,$H28,'Trans March'!$H:$H)) -> 0 | L28: =IF(ISBLANK($H28), "", K28-J28) -> 0
B29: Groceries | D29: 500000 | E29: =IF(ISBLANK($B29), "", SUMIF('Trans March'!$E:$E,$B29,'Trans March'!$C:$C)) -> 0 | F29: =IF(ISBLANK($B29), "", D29-E29) -> 500000 | H29: Paycheck | K29: =IF(ISBLANK($H29), "", SUMIF('Trans March'!$J:$J,$H29,'Trans March'!$H:$H)) -> 0 | L29: =IF(ISBLANK($H29), "", K29-J29) -> 0
B30: Internet | D30: 600000 | E30: =IF(ISBLANK($B30), "", SUMIF('Trans March'!$E:$E,$B30,'Trans March'!$C:$C)) -> 0 | F30: =IF(ISBLANK($B30), "", D30-E30) -> 600000 | H30: Bonus | K30: =IF(ISBLANK($H30), "", SUMIF('Trans March'!$J:$J,$H30,'Trans March'!$H:$H)) -> 0 | L30: =IF(ISBLANK($H30), "", K30-J30) -> 0
B31: Kids | D31: 5000000 | E31: =IF(ISBLANK($B31), "", SUMIF('Trans March'!$E:$E,$B31,'Trans March'!$C:$C)) -> 0 | F31: =IF(ISBLANK($B31), "", D31-E31) -> 5000000 | H31: Interest | K31: =IF(ISBLANK($H31), "", SUMIF('Trans March'!$J:$J,$H31,'Trans March'!$H:$H)) -> 0 | L31: =IF(ISBLANK($H31), "", K31-J31) -> 0
B32: Transportation | D32: 4000000 | E32: =IF(ISBLANK($B32), "", SUMIF('Trans March'!$E:$E,$B32,'Trans March'!$C:$C)) -> 0 | F32: =IF(ISBLANK($B32), "", D32-E32) -> 4000000 | H32: Affiliate | K32: =IF(ISBLANK($H32), "", SUMIF('Trans March'!$J:$J,$H32,'Trans March'!$H:$H)) -> 0 | L32: =IF(ISBLANK($H32), "", K32-J32) -> 0
B33: Shopping | D33: 1500000 | E33: =IF(ISBLANK($B33), "", SUMIF('Trans March'!$E:$E,$B33,'Trans March'!$C:$C)) -> 0 | F33: =IF(ISBLANK($B33), "", D33-E33) -> 1500000 | H33: IKS | K33: =IF(ISBLANK($H33), "", SUMIF('Trans March'!$J:$J,$H33,'Trans March'!$H:$H)) -> 0 | L33: =IF(ISBLANK($H33), "", K33-J33) -> 0
B34: Entertain | D34: 500000 | E34: =IF(ISBLANK($B34), "", SUMIF('Trans March'!$E:$E,$B34,'Trans March'!$C:$C)) -> 0 | F34: =IF(ISBLANK($B34), "", D34-E34) -> 500000 | H34: Endorsement | K34: =IF(ISBLANK($H34), "", SUMIF('Trans March'!$J:$J,$H34,'Trans March'!$H:$H)) -> 0 | L34: =IF(ISBLANK($H34), "", K34-J34) -> 0
B35: Home and Laundry | D35: 500000 | E35: =IF(ISBLANK($B35), "", SUMIF('Trans March'!$E:$E,$B35,'Trans March'!$C:$C)) -> 0 | F35: =IF(ISBLANK($B35), "", D35-E35) -> 500000 | K35: =IF(ISBLANK($H35), "", SUMIF('Trans March'!$J:$J,$H35,'Trans March'!$H:$H)) | L35: =IF(ISBLANK($H35), "", K35-J35)
B36: Listrik | D36: 500000 | E36: =IF(ISBLANK($B36), "", SUMIF('Trans March'!$E:$E,$B36,'Trans March'!$C:$C)) -> 0 | F36: =IF(ISBLANK($B36), "", D36-E36) -> 500000 | K36: =IF(ISBLANK($H36), "", SUMIF('Trans March'!$J:$J,$H36,'Trans March'!$H:$H)) | L36: =IF(ISBLANK($H36), "", K36-J36)
B37: Health/Bodycare | D37: 500000 | E37: =IF(ISBLANK($B37), "", SUMIF('Trans March'!$E:$E,$B37,'Trans March'!$C:$C)) -> 0 | F37: =IF(ISBLANK($B37), "", D37-E37) -> 500000 | K37: =IF(ISBLANK($H37), "", SUMIF('Trans March'!$J:$J,$H37,'Trans March'!$H:$H)) | L37: =IF(ISBLANK($H37), "", K37-J37)
B38: Content dan PP | D38: 200000 | E38: =IF(ISBLANK($B38), "", SUMIF('Trans March'!$E:$E,$B38,'Trans March'!$C:$C)) -> 0 | F38: =IF(ISBLANK($B38), "", D38-E38) -> 200000 | K38: =IF(ISBLANK($H38), "", SUMIF('Trans March'!$J:$J,$H38,'Trans March'!$H:$H)) | L38: =IF(ISBLANK($H38), "", K38-J38)
B39: Koperasi | D39: 150000 | E39: =IF(ISBLANK($B39), "", SUMIF('Trans March'!$E:$E,$B39,'Trans March'!$C:$C)) -> 0 | F39: =IF(ISBLANK($B39), "", D39-E39) -> 150000 | K39: =IF(ISBLANK($H39), "", SUMIF('Trans March'!$J:$J,$H39,'Trans March'!$H:$H)) | L39: =IF(ISBLANK($H39), "", K39-J39)
B40: Gifts/charity | D40: 1500000 | E40: =IF(ISBLANK($B40), "", SUMIF('Trans March'!$E:$E,$B40,'Trans March'!$C:$C)) -> 0 | F40: =IF(ISBLANK($B40), "", D40-E40) -> 1500000 | K40: =IF(ISBLANK($H40), "", SUMIF('Trans March'!$J:$J,$H40,'Trans March'!$H:$H)) | L40: =IF(ISBLANK($H40), "", K40-J40)
B41: Lending | D41: 0 | E41: =IF(ISBLANK($B41), "", SUMIF('Trans March'!$E:$E,$B41,'Trans March'!$C:$C)) -> 0 | F41: =IF(ISBLANK($B41), "", D41-E41) -> 0 | K41: =IF(ISBLANK($H41), "", SUMIF('Trans March'!$J:$J,$H41,'Trans March'!$H:$H)) | L41: =IF(ISBLANK($H41), "", K41-J41)
B42: SPPD | D42: 0 | E42: =IF(ISBLANK($B42), "", SUMIF('Trans March'!$E:$E,$B42,'Trans March'!$C:$C)) -> 0 | F42: =IF(ISBLANK($B42), "", D42-E42) -> 0 | K42: =IF(ISBLANK($H42), "", SUMIF('Trans March'!$J:$J,$H42,'Trans March'!$H:$H)) | L42: =IF(ISBLANK($H42), "", K42-J42)
F43: =IF(ISBLANK($B43), "", D43-E43) | K43: =IF(ISBLANK($H43), "", SUMIF('Trans March'!$J:$J,$H43,'Trans March'!$H:$H)) | L43: =IF(ISBLANK($H43), "", K43-J43)
E44: =IF(ISBLANK($B44), "", SUMIF('Trans March'!$E:$E,$B44,'Trans March'!$C:$C)) | K44: =IF(ISBLANK($H44), "", SUMIF('Trans March'!$J:$J,$H44,'Trans March'!$H:$H)) | L44: =IF(ISBLANK($H44), "", K44-J44)

Sheet Trans March
B1: Change or add categories by updating the Expenses and Income tables in the Summary sheet.
B2: Expenses | G2: Income
B4: Date | C4: Amount | D4: Description | E4: Category | G4: Date | H4: Amount | I4: Description | J4: Category

Sheet April
B2: GET STARTED | I2: NOTE
B3: Set your starting balance in cell L8, then customize your categories and planned spending amounts in the 'Income' and 'Expenses' tables below. | I3: Only edit highlighted cells.
I4: Try not to alter cells that contain a formula.
B5: As you enter data in the 'Transactions' tab, this sheet will automatically update to show a summary of your spending for the month.
B8: Monthly Budget | J8: Starting balance: | L8: =March!E17 -> 3000000
D12: =IFERROR(__xludf.DUMMYFUNCTION("SPARKLINE(D17,{""charttype"",""column"";""ymin"", 0; ""ymax"",MAX(D17:E17);""firstcolor"",""#334960""})"),"") | E12: =IFERROR(__xludf.DUMMYFUNCTION("SPARKLINE(E17,{""charttype"",""column"";""ymin"", 0; ""ymax"",max(D17:E17);""firstcolor"",""#f46524""})"),"")
I13: =IFERROR(E17/D17-1, "") -> 0
I14: =IF(I13 < 0, "Decrease in total savings", "Increase in total savings") -> Increase in total savings
I15: =IFERROR(E17-D17, 0) -> 0
D16: START BALANCE | E16: END BALANCE | I16: =IF(J15<0, "Spent this month", "Saved this month") -> Saved this month
D17: =IF(ISBLANK(L8),0,L8) -> 3000000 | E17: =D17+(I22-C22) -> 3000000
E18: =SUM(I7:I10)+SUM(G7:G10) -> 0
B20: Expenses | H20: Income
B21: Planned | C21: =D26 -> 22450000 | D21: =IFERROR(__xludf.DUMMYFUNCTION("SPARKLINE(C21,{""charttype"",""bar"";""max"",max(C21:C22);""color1"",""#AEB7C0""})"),"") | H21: Planned | I21: =J26 -> 0 | J21: =IFERROR(__xludf.DUMMYFUNCTION("SPARKLINE(I21,{""charttype"",""bar"";""max"",max(I21:I22);""color1"",""#AEB7C0""})"),"")
B22: Actual | C22: =E26 -> 0 | D22: =IFERROR(__xludf.DUMMYFUNCTION("SPARKLINE(C22,{""charttype"",""bar"";""max"",max(C21:C22);""color1"",""#334960""})"),"") | H22: Actual | I22: =K26 -> 0 | J22: =IFERROR(__xludf.DUMMYFUNCTION("SPARKLINE(I22,{""charttype"",""bar"";""max"",max(I21:I22);""color1"",""#334960""})"),"")
B24: Expenses | H24: Income
D25: Planned | E25: Actual | F25: Diff. | J25: Planned | K25: Actual | L25: Diff.
B26: Totals | D26: =SUM(D27:D1044) -> 22450000 | E26: =SUM(E27:E1044) -> 0 | F26: =SUM(F27:F1044) -> 22450000 | H26: Totals | J26: =SUM(J27:J44) -> 0 | K26: =SUM(K27:K44) -> 0 | L26: =SUM(L27:L44) -> 0
E27: =IF(ISBLANK($B27), "", SUMIF('Trans April'!$E:$E,$B27,'Trans April'!$C:$C)) | F27: =IF(ISBLANK($B27), "", D27-E27) | K27: =IF(ISBLANK($H27), "", SUMIF('Trans April'!$J:$J,$H27,'Trans April'!$H:$H)) | L27: =IF(ISBLANK($H27), "", K27-J27)
B28: Food | D28: 7000000 | E28: =IF(ISBLANK($B28), "", SUMIF('Trans April'!$E:$E,$B28,'Trans April'!$C:$C)) -> 0 | F28: =IF(ISBLANK($B28), "", D28-E28) -> 7000000 | H28: Savings | K28: =IF(ISBLANK($H28), "", SUMIF('Trans April'!$J:$J,$H28,'Trans April'!$H:$H)) -> 0 | L28: =IF(ISBLANK($H28), "", K28-J28) -> 0
B29: Groceries | D29: 500000 | E29: =IF(ISBLANK($B29), "", SUMIF('Trans April'!$E:$E,$B29,'Trans April'!$C:$C)) -> 0 | F29: =IF(ISBLANK($B29), "", D29-E29) -> 500000 | H29: Paycheck | K29: =IF(ISBLANK($H29), "", SUMIF('Trans April'!$J:$J,$H29,'Trans April'!$H:$H)) -> 0 | L29: =IF(ISBLANK($H29), "", K29-J29) -> 0
B30: Internet | D30: 600000 | E30: =IF(ISBLANK($B30), "", SUMIF('Trans April'!$E:$E,$B30,'Trans April'!$C:$C)) -> 0 | F30: =IF(ISBLANK($B30), "", D30-E30) -> 600000 | H30: Bonus | K30: =IF(ISBLANK($H30), "", SUMIF('Trans April'!$J:$J,$H30,'Trans April'!$H:$H)) -> 0 | L30: =IF(ISBLANK($H30), "", K30-J30) -> 0
B31: Kids | D31: 5000000 | E31: =IF(ISBLANK($B31), "", SUMIF('Trans April'!$E:$E,$B31,'Trans April'!$C:$C)) -> 0 | F31: =IF(ISBLANK($B31), "", D31-E31) -> 5000000 | H31: Interest | K31: =IF(ISBLANK($H31), "", SUMIF('Trans April'!$J:$J,$H31,'Trans April'!$H:$H)) -> 0 | L31: =IF(ISBLANK($H31), "", K31-J31) -> 0
B32: Transportation | D32: 4000000 | E32: =IF(ISBLANK($B32), "", SUMIF('Trans April'!$E:$E,$B32,'Trans April'!$C:$C)) -> 0 | F32: =IF(ISBLANK($B32), "", D32-E32) -> 4000000 | H32: Affiliate | K32: =IF(ISBLANK($H32), "", SUMIF('Trans April'!$J:$J,$H32,'Trans April'!$H:$H)) -> 0 | L32: =IF(ISBLANK($H32), "", K32-J32) -> 0
B33: Shopping | D33: 1500000 | E33: =IF(ISBLANK($B33), "", SUMIF('Trans April'!$E:$E,$B33,'Trans April'!$C:$C)) -> 0 | F33: =IF(ISBLANK($B33), "", D33-E33) -> 1500000 | H33: IKS | K33: =IF(ISBLANK($H33), "", SUMIF('Trans April'!$J:$J,$H33,'Trans April'!$H:$H)) -> 0 | L33: =IF(ISBLANK($H33), "", K33-J33) -> 0
B34: Entertain | D34: 500000 | E34: =IF(ISBLANK($B34), "", SUMIF('Trans April'!$E:$E,$B34,'Trans April'!$C:$C)) -> 0 | F34: =IF(ISBLANK($B34), "", D34-E34) -> 500000 | H34: Endorsement | K34: =IF(ISBLANK($H34), "", SUMIF('Trans April'!$J:$J,$H34,'Trans April'!$H:$H)) -> 0 | L34: =IF(ISBLANK($H34), "", K34-J34) -> 0
B35: Home and Laundry | D35: 500000 | E35: =IF(ISBLANK($B35), "", SUMIF('Trans April'!$E:$E,$B35,'Trans April'!$C:$C)) -> 0 | F35: =IF(ISBLANK($B35), "", D35-E35) -> 500000 | K35: =IF(ISBLANK($H35), "", SUMIF('Trans April'!$J:$J,$H35,'Trans April'!$H:$H)) | L35: =IF(ISBLANK($H35), "", K35-J35)
B36: Listrik | D36: 500000 | E36: =IF(ISBLANK($B36), "", SUMIF('Trans April'!$E:$E,$B36,'Trans April'!$C:$C)) -> 0 | F36: =IF(ISBLANK($B36), "", D36-E36) -> 500000 | K36: =IF(ISBLANK($H36), "", SUMIF('Trans April'!$J:$J,$H36,'Trans April'!$H:$H)) | L36: =IF(ISBLANK($H36), "", K36-J36)
B37: Health/Bodycare | D37: 500000 | E37: =IF(ISBLANK($B37), "", SUMIF('Trans April'!$E:$E,$B37,'Trans April'!$C:$C)) -> 0 | F37: =IF(ISBLANK($B37), "", D37-E37) -> 500000 | K37: =IF(ISBLANK($H37), "", SUMIF('Trans April'!$J:$J,$H37,'Trans April'!$H:$H)) | L37: =IF(ISBLANK($H37), "", K37-J37)
B38: Content dan PP | D38: 200000 | E38: =IF(ISBLANK($B38), "", SUMIF('Trans April'!$E:$E,$B38,'Trans April'!$C:$C)) -> 0 | F38: =IF(ISBLANK($B38), "", D38-E38) -> 200000 | K38: =IF(ISBLANK($H38), "", SUMIF('Trans April'!$J:$J,$H38,'Trans April'!$H:$H)) | L38: =IF(ISBLANK($H38), "", K38-J38)
B39: Koperasi | D39: 150000 | E39: =IF(ISBLANK($B39), "", SUMIF('Trans April'!$E:$E,$B39,'Trans April'!$C:$C)) -> 0 | F39: =IF(ISBLANK($B39), "", D39-E39) -> 150000 | K39: =IF(ISBLANK($H39), "", SUMIF('Trans April'!$J:$J,$H39,'Trans April'!$H:$H)) | L39: =IF(ISBLANK($H39), "", K39-J39)
B40: Gifts/charity | D40: 1500000 | E40: =IF(ISBLANK($B40), "", SUMIF('Trans April'!$E:$E,$B40,'Trans April'!$C:$C)) -> 0 | F40: =IF(ISBLANK($B40), "", D40-E40) -> 1500000 | K40: =IF(ISBLANK($H40), "", SUMIF('Trans April'!$J:$J,$H40,'Trans April'!$H:$H)) | L40: =IF(ISBLANK($H40), "", K40-J40)
B41: Lending | D41: 0 | E41: =IF(ISBLANK($B41), "", SUMIF('Trans April'!$E:$E,$B41,'Trans April'!$C:$C)) -> 0 | F41: =IF(ISBLANK($B41), "", D41-E41) -> 0 | K41: =IF(ISBLANK($H41), "", SUMIF('Trans April'!$J:$J,$H41,'Trans April'!$H:$H)) | L41: =IF(ISBLANK($H41), "", K41-J41)
B42: SPPD | D42: 0 | E42: =IF(ISBLANK($B42), "", SUMIF('Trans April'!$E:$E,$B42,'Trans April'!$C:$C)) -> 0 | F42: =IF(ISBLANK($B42), "", D42-E42) -> 0 | K42: =IF(ISBLANK($H42), "", SUMIF('Trans April'!$J:$J,$H42,'Trans April'!$H:$H)) | L42: =IF(ISBLANK($H42), "", K42-J42)
F43: =IF(ISBLANK($B43), "", D43-E43) | K43: =IF(ISBLANK($H43), "", SUMIF('Trans April'!$J:$J,$H43,'Trans April'!$H:$H)) | L43: =IF(ISBLANK($H43), "", K43-J43)
E44: =IF(ISBLANK($B44), "", SUMIF('Trans April'!$E:$E,$B44,'Trans April'!$C:$C)) | K44: =IF(ISBLANK($H44), "", SUMIF('Trans April'!$J:$J,$H44,'Trans April'!$H:$H)) | L44: =IF(ISBLANK($H44), "", K44-J44)

Sheet Trans April
B1: Change or add categories by updating the Expenses and Income tables in the Summary sheet.
B2: Expenses | G2: Income
B4: Date | C4: Amount | D4: Description | E4: Category | G4: Date | H4: Amount | I4: Description | J4: Category

Sheet Mei
B2: GET STARTED | I2: NOTE
B3: Set your starting balance in cell L8, then customize your categories and planned spending amounts in the 'Income' and 'Expenses' tables below. | I3: Only edit highlighted cells.
I4: Try not to alter cells that contain a formula.
B5: As you enter data in the 'Transactions' tab, this sheet will automatically update to show a summary of your spending for the month.
B8: Monthly Budget | J8: Starting balance: | L8: =April!E17 -> 3000000
D12: =IFERROR(__xludf.DUMMYFUNCTION("SPARKLINE(D17,{""charttype"",""column"";""ymin"", 0; ""ymax"",MAX(D17:E17);""firstcolor"",""#334960""})"),"") | E12: =IFERROR(__xludf.DUMMYFUNCTION("SPARKLINE(E17,{""charttype"",""column"";""ymin"", 0; ""ymax"",max(D17:E17);""firstcolor"",""#f46524""})"),"")
I13: =IFERROR(E17/D17-1, "") -> 0
I14: =IF(I13 < 0, "Decrease in total savings", "Increase in total savings") -> Increase in total savings
I15: =IFERROR(E17-D17, 0) -> 0
D16: START BALANCE | E16: END BALANCE | I16: =IF(J15<0, "Spent this month", "Saved this month") -> Saved this month
D17: =IF(ISBLANK(L8),0,L8) -> 3000000 | E17: =D17+(I22-C22) -> 3000000
E18: =SUM(I7:I10)+SUM(G7:G10) -> 0
B20: Expenses | H20: Income
B21: Planned | C21: =D26 -> 22450000 | D21: =IFERROR(__xludf.DUMMYFUNCTION("SPARKLINE(C21,{""charttype"",""bar"";""max"",max(C21:C22);""color1"",""#AEB7C0""})"),"") | H21: Planned | I21: =J26 -> 0 | J21: =IFERROR(__xludf.DUMMYFUNCTION("SPARKLINE(I21,{""charttype"",""bar"";""max"",max(I21:I22);""color1"",""#AEB7C0""})"),"")
B22: Actual | C22: =E26 -> 0 | D22: =IFERROR(__xludf.DUMMYFUNCTION("SPARKLINE(C22,{""charttype"",""bar"";""max"",max(C21:C22);""color1"",""#334960""})"),"") | H22: Actual | I22: =K26 -> 0 | J22: =IFERROR(__xludf.DUMMYFUNCTION("SPARKLINE(I22,{""charttype"",""bar"";""max"",max(I21:I22);""color1"",""#334960""})"),"")
B24: Expenses | H24: Income
D25: Planned | E25: Actual | F25: Diff. | J25: Planned | K25: Actual | L25: Diff.
B26: Totals | D26: =SUM(D27:D1044) -> 22450000 | E26: =SUM(E27:E1044) -> 0 | F26: =SUM(F27:F1044) -> 22450000 | H26: Totals | J26: =SUM(J27:J44) -> 0 | K26: =SUM(K27:K44) -> 0 | L26: =SUM(L27:L44) -> 0
E27: =IF(ISBLANK($B27), "", SUMIF('Trans Mei'!$E:$E,$B27,'Trans Mei'!$C:$C)) | F27: =IF(ISBLANK($B27), "", D27-E27) | K27: =IF(ISBLANK($H27), "", SUMIF('Trans Mei'!$J:$J,$H27,'Trans Mei'!$H:$H)) | L27: =IF(ISBLANK($H27), "", K27-J27)
B28: Food | D28: 7000000 | E28: =IF(ISBLANK($B28), "", SUMIF('Trans Mei'!$E:$E,$B28,'Trans Mei'!$C:$C)) -> 0 | F28: =IF(ISBLANK($B28), "", D28-E28) -> 7000000 | H28: Savings | K28: =IF(ISBLANK($H28), "", SUMIF('Trans Mei'!$J:$J,$H28,'Trans Mei'!$H:$H)) -> 0 | L28: =IF(ISBLANK($H28), "", K28-J28) -> 0
B29: Groceries | D29: 500000 | E29: =IF(ISBLANK($B29), "", SUMIF('Trans Mei'!$E:$E,$B29,'Trans Mei'!$C:$C)) -> 0 | F29: =IF(ISBLANK($B29), "", D29-E29) -> 500000 | H29: Paycheck | K29: =IF(ISBLANK($H29), "", SUMIF('Trans Mei'!$J:$J,$H29,'Trans Mei'!$H:$H)) -> 0 | L29: =IF(ISBLANK($H29), "", K29-J29) -> 0
B30: Internet | D30: 600000 | E30: =IF(ISBLANK($B30), "", SUMIF('Trans Mei'!$E:$E,$B30,'Trans Mei'!$C:$C)) -> 0 | F30: =IF(ISBLANK($B30), "", D30-E30) -> 600000 | H30: Bonus | K30: =IF(ISBLANK($H30), "", SUMIF('Trans Mei'!$J:$J,$H30,'Trans Mei'!$H:$H)) -> 0 | L30: =IF(ISBLANK($H30), "", K30-J30) -> 0
B31: Kids | D31: 5000000 | E31: =IF(ISBLANK($B31), "", SUMIF('Trans Mei'!$E:$E,$B31,'Trans Mei'!$C:$C)) -> 0 | F31: =IF(ISBLANK($B31), "", D31-E31) -> 5000000 | H31: Interest | K31: =IF(ISBLANK($H31), "", SUMIF('Trans Mei'!$J:$J,$H31,'Trans Mei'!$H:$H)) -> 0 | L31: =IF(ISBLANK($H31), "", K31-J31) -> 0
B32: Transportation | D32: 4000000 | E32: =IF(ISBLANK($B32), "", SUMIF('Trans Mei'!$E:$E,$B32,'Trans Mei'!$C:$C)) -> 0 | F32: =IF(ISBLANK($B32), "", D32-E32) -> 4000000 | H32: Affiliate | K32: =IF(ISBLANK($H32), "", SUMIF('Trans Mei'!$J:$J,$H32,'Trans Mei'!$H:$H)) -> 0 | L32: =IF(ISBLANK($H32), "", K32-J32) -> 0
B33: Shopping | D33: 1500000 | E33: =IF(ISBLANK($B33), "", SUMIF('Trans Mei'!$E:$E,$B33,'Trans Mei'!$C:$C)) -> 0 | F33: =IF(ISBLANK($B33), "", D33-E33) -> 1500000 | H33: IKS | K33: =IF(ISBLANK($H33), "", SUMIF('Trans Mei'!$J:$J,$H33,'Trans Mei'!$H:$H)) -> 0 | L33: =IF(ISBLANK($H33), "", K33-J33) -> 0
B34: Entertain | D34: 500000 | E34: =IF(ISBLANK($B34), "", SUMIF('Trans Mei'!$E:$E,$B34,'Trans Mei'!$C:$C)) -> 0 | F34: =IF(ISBLANK($B34), "", D34-E34) -> 500000 | H34: Endorsement | K34: =IF(ISBLANK($H34), "", SUMIF('Trans Mei'!$J:$J,$H34,'Trans Mei'!$H:$H)) -> 0 | L34: =IF(ISBLANK($H34), "", K34-J34) -> 0
B35: Home and Laundry | D35: 500000 | E35: =IF(ISBLANK($B35), "", SUMIF('Trans Mei'!$E:$E,$B35,'Trans Mei'!$C:$C)) -> 0 | F35: =IF(ISBLANK($B35), "", D35-E35) -> 500000 | K35: =IF(ISBLANK($H35), "", SUMIF('Trans Mei'!$J:$J,$H35,'Trans Mei'!$H:$H)) | L35: =IF(ISBLANK($H35), "", K35-J35)
B36: Listrik | D36: 500000 | E36: =IF(ISBLANK($B36), "", SUMIF('Trans Mei'!$E:$E,$B36,'Trans Mei'!$C:$C)) -> 0 | F36: =IF(ISBLANK($B36), "", D36-E36) -> 500000 | K36: =IF(ISBLANK($H36), "", SUMIF('Trans Mei'!$J:$J,$H36,'Trans Mei'!$H:$H)) | L36: =IF(ISBLANK($H36), "", K36-J36)
B37: Health/Bodycare | D37: 500000 | E37: =IF(ISBLANK($B37), "", SUMIF('Trans Mei'!$E:$E,$B37,'Trans Mei'!$C:$C)) -> 0 | F37: =IF(ISBLANK($B37), "", D37-E37) -> 500000 | K37: =IF(ISBLANK($H37), "", SUMIF('Trans Mei'!$J:$J,$H37,'Trans Mei'!$H:$H)) | L37: =IF(ISBLANK($H37), "", K37-J37)
B38: Content dan PP | D38: 200000 | E38: =IF(ISBLANK($B38), "", SUMIF('Trans Mei'!$E:$E,$B38,'Trans Mei'!$C:$C)) -> 0 | F38: =IF(ISBLANK($B38), "", D38-E38) -> 200000 | K38: =IF(ISBLANK($H38), "", SUMIF('Trans Mei'!$J:$J,$H38,'Trans Mei'!$H:$H)) | L38: =IF(ISBLANK($H38), "", K38-J38)
B39: Koperasi | D39: 150000 | E39: =IF(ISBLANK($B39), "", SUMIF('Trans Mei'!$E:$E,$B39,'Trans Mei'!$C:$C)) -> 0 | F39: =IF(ISBLANK($B39), "", D39-E39) -> 150000 | K39: =IF(ISBLANK($H39), "", SUMIF('Trans Mei'!$J:$J,$H39,'Trans Mei'!$H:$H)) | L39: =IF(ISBLANK($H39), "", K39-J39)
B40: Gifts/charity | D40: 1500000 | E40: =IF(ISBLANK($B40), "", SUMIF('Trans Mei'!$E:$E,$B40,'Trans Mei'!$C:$C)) -> 0 | F40: =IF(ISBLANK($B40), "", D40-E40) -> 1500000 | K40: =IF(ISBLANK($H40), "", SUMIF('Trans Mei'!$J:$J,$H40,'Trans Mei'!$H:$H)) | L40: =IF(ISBLANK($H40), "", K40-J40)
B41: Lending | D41: 0 | E41: =IF(ISBLANK($B41), "", SUMIF('Trans Mei'!$E:$E,$B41,'Trans Mei'!$C:$C)) -> 0 | F41: =IF(ISBLANK($B41), "", D41-E41) -> 0 | K41: =IF(ISBLANK($H41), "", SUMIF('Trans Mei'!$J:$J,$H41,'Trans Mei'!$H:$H)) | L41: =IF(ISBLANK($H41), "", K41-J41)
B42: SPPD | D42: 0 | E42: =IF(ISBLANK($B42), "", SUMIF('Trans Mei'!$E:$E,$B42,'Trans Mei'!$C:$C)) -> 0 | F42: =IF(ISBLANK($B42), "", D42-E42) -> 0 | K42: =IF(ISBLANK($H42), "", SUMIF('Trans Mei'!$J:$J,$H42,'Trans Mei'!$H:$H)) | L42: =IF(ISBLANK($H42), "", K42-J42)
F43: =IF(ISBLANK($B43), "", D43-E43) | K43: =IF(ISBLANK($H43), "", SUMIF('Trans Mei'!$J:$J,$H43,'Trans Mei'!$H:$H)) | L43: =IF(ISBLANK($H43), "", K43-J43)
E44: =IF(ISBLANK($B44), "", SUMIF('Trans Mei'!$E:$E,$B44,'Trans Mei'!$C:$C)) | K44: =IF(ISBLANK($H44), "", SUMIF('Trans Mei'!$J:$J,$H44,'Trans Mei'!$H:$H)) | L44: =IF(ISBLANK($H44), "", K44-J44)

Sheet Trans Mei
B1: Change or add categories by updating the Expenses and Income tables in the Summary sheet.
B2: Expenses | G2: Income
B4: Date | C4: Amount | D4: Description | E4: Category | G4: Date | H4: Amount | I4: Description | J4: Category

Sheet Juni
B2: GET STARTED | I2: NOTE
B3: Set your starting balance in cell L8, then customize your categories and planned spending amounts in the 'Income' and 'Expenses' tables below. | I3: Only edit highlighted cells.
I4: Try not to alter cells that contain a formula.
B5: As you enter data in the 'Transactions' tab, this sheet will automatically update to show a summary of your spending for the month.
B8: Monthly Budget | J8: Starting balance: | L8: =Mei!E17 -> 3000000
D12: =IFERROR(__xludf.DUMMYFUNCTION("SPARKLINE(D17,{""charttype"",""column"";""ymin"", 0; ""ymax"",MAX(D17:E17);""firstcolor"",""#334960""})"),"") | E12: =IFERROR(__xludf.DUMMYFUNCTION("SPARKLINE(E17,{""charttype"",""column"";""ymin"", 0; ""ymax"",max(D17:E17);""firstcolor"",""#f46524""})"),"")
I13: =IFERROR(E17/D17-1, "") -> 0
I14: =IF(I13 < 0, "Decrease in total savings", "Increase in total savings") -> Increase in total savings
I15: =IFERROR(E17-D17, 0) -> 0
D16: START BALANCE | E16: END BALANCE | I16: =IF(J15<0, "Spent this month", "Saved this month") -> Saved this month
D17: =IF(ISBLANK(L8),0,L8) -> 3000000 | E17: =D17+(I22-C22) -> 3000000
E18: =SUM(I7:I10)+SUM(G7:G10) -> 0
B20: Expenses | H20: Income
B21: Planned | C21: =D26 -> 22450000 | D21: =IFERROR(__xludf.DUMMYFUNCTION("SPARKLINE(C21,{""charttype"",""bar"";""max"",max(C21:C22);""color1"",""#AEB7C0""})"),"") | H21: Planned | I21: =J26 -> 0 | J21: =IFERROR(__xludf.DUMMYFUNCTION("SPARKLINE(I21,{""charttype"",""bar"";""max"",max(I21:I22);""color1"",""#AEB7C0""})"),"")
B22: Actual | C22: =E26 -> 0 | D22: =IFERROR(__xludf.DUMMYFUNCTION("SPARKLINE(C22,{""charttype"",""bar"";""max"",max(C21:C22);""color1"",""#334960""})"),"") | H22: Actual | I22: =K26 -> 0 | J22: =IFERROR(__xludf.DUMMYFUNCTION("SPARKLINE(I22,{""charttype"",""bar"";""max"",max(I21:I22);""color1"",""#334960""})"),"")
B24: Expenses | H24: Income
D25: Planned | E25: Actual | F25: Diff. | J25: Planned | K25: Actual | L25: Diff.
B26: Totals | D26: =SUM(D27:D1044) -> 22450000 | E26: =SUM(E27:E1044) -> 0 | F26: =SUM(F27:F1044) -> 22450000 | H26: Totals | J26: =SUM(J27:J44) -> 0 | K26: =SUM(K27:K44) -> 0 | L26: =SUM(L27:L44) -> 0
E27: =IF(ISBLANK($B27), "", SUMIF('Trans Jun'!$E:$E,$B27,'Trans Jun'!$C:$C)) | F27: =IF(ISBLANK($B27), "", D27-E27) | K27: =IF(ISBLANK($H27), "", SUMIF('Trans Jun'!$J:$J,$H27,'Trans Jun'!$H:$H)) | L27: =IF(ISBLANK($H27), "", K27-J27)
B28: Food | D28: 7000000 | E28: =IF(ISBLANK($B28), "", SUMIF('Trans Jun'!$E:$E,$B28,'Trans Jun'!$C:$C)) -> 0 | F28: =IF(ISBLANK($B28), "", D28-E28) -> 7000000 | H28: Savings | K28: =IF(ISBLANK($H28), "", SUMIF('Trans Jun'!$J:$J,$H28,'Trans Jun'!$H:$H)) -> 0 | L28: =IF(ISBLANK($H28), "", K28-J28) -> 0
B29: Groceries | D29: 500000 | E29: =IF(ISBLANK($B29), "", SUMIF('Trans Jun'!$E:$E,$B29,'Trans Jun'!$C:$C)) -> 0 | F29: =IF(ISBLANK($B29), "", D29-E29) -> 500000 | H29: Paycheck | K29: =IF(ISBLANK($H29), "", SUMIF('Trans Jun'!$J:$J,$H29,'Trans Jun'!$H:$H)) -> 0 | L29: =IF(ISBLANK($H29), "", K29-J29) -> 0
B30: Internet | D30: 600000 | E30: =IF(ISBLANK($B30), "", SUMIF('Trans Jun'!$E:$E,$B30,'Trans Jun'!$C:$C)) -> 0 | F30: =IF(ISBLANK($B30), "", D30-E30) -> 600000 | H30: Bonus | K30: =IF(ISBLANK($H30), "", SUMIF('Trans Jun'!$J:$J,$H30,'Trans Jun'!$H:$H)) -> 0 | L30: =IF(ISBLANK($H30), "", K30-J30) -> 0
B31: Kids | D31: 5000000 | E31: =IF(ISBLANK($B31), "", SUMIF('Trans Jun'!$E:$E,$B31,'Trans Jun'!$C:$C)) -> 0 | F31: =IF(ISBLANK($B31), "", D31-E31) -> 5000000 | H31: Interest | K31: =IF(ISBLANK($H31), "", SUMIF('Trans Jun'!$J:$J,$H31,'Trans Jun'!$H:$H)) -> 0 | L31: =IF(ISBLANK($H31), "", K31-J31) -> 0
